Exception lors du chargement de la clé publique: HTTPConnectionPool(host='localhost', port=8080): Max retries exceeded with url: /auth/realms/livraison-abidjan (Caused by NewConnectionError('<urllib3.connection.HTTPConnection object at 0x000001BEE0528230>: Failed to establish a new connection: [WinError 10061] Aucune connexion n’a pu être établie car l’ordinateur cible l’a expressément refusée'))
E:\delivery-app\delivery-app-abidjan\backend\venv\Lib\site-packages\pydantic\_internal\_config.py:269: UserWarning: Valid config keys have changed in V2:
* 'orm_mode' has been renamed to 'from_attributes'
  warnings.warn(message, UserWarning)
Process SpawnProcess-2:
Traceback (most recent call last):
  File "C:\Python312\Lib\multiprocessing\process.py", line 314, in _bootstrap
    self.run()
  File "C:\Python312\Lib\multiprocessing\process.py", line 108, in run
    self._target(*self._args, **self._kwargs)
  File "E:\delivery-app\delivery-app-abidjan\backend\venv\Lib\site-packages\uvicorn\_subprocess.py", line 76, in subprocess_started
    target(sockets=sockets)
  File "E:\delivery-app\delivery-app-abidjan\backend\venv\Lib\site-packages\uvicorn\server.py", line 61, in run      
    return asyncio.run(self.serve(sockets=sockets))
           ^^^^^^^^^^^^^^^^^^^^^^^^^^^^^^^^^^^^^^^^
  File "C:\Python312\Lib\asyncio\runners.py", line 194, in run
    return runner.run(main)
           ^^^^^^^^^^^^^^^^
  File "C:\Python312\Lib\asyncio\runners.py", line 118, in run
    return self._loop.run_until_complete(task)
           ^^^^^^^^^^^^^^^^^^^^^^^^^^^^^^^^^^^
  File "C:\Python312\Lib\asyncio\base_events.py", line 664, in run_until_complete
    return future.result()
           ^^^^^^^^^^^^^^^
  File "E:\delivery-app\delivery-app-abidjan\backend\venv\Lib\site-packages\uvicorn\server.py", line 68, in serve    
    config.load()
  File "E:\delivery-app\delivery-app-abidjan\backend\venv\Lib\site-packages\uvicorn\config.py", line 467, in load    
    self.loaded_app = import_from_string(self.app)
                      ^^^^^^^^^^^^^^^^^^^^^^^^^^^^
  File "E:\delivery-app\delivery-app-abidjan\backend\venv\Lib\site-packages\uvicorn\importer.py", line 21, in import_from_string
    module = importlib.import_module(module_str)
             ^^^^^^^^^^^^^^^^^^^^^^^^^^^^^^^^^^^
  File "C:\Python312\Lib\importlib\__init__.py", line 90, in import_module
    return _bootstrap._gcd_import(name[level:], package, level)
           ^^^^^^^^^^^^^^^^^^^^^^^^^^^^^^^^^^^^^^^^^^^^^^^^^^^^
  File "<frozen importlib._bootstrap>", line 1381, in _gcd_import
  File "<frozen importlib._bootstrap>", line 1354, in _find_and_load
  File "<frozen importlib._bootstrap>", line 1325, in _find_and_load_unlocked
  File "<frozen importlib._bootstrap>", line 929, in _load_unlocked
  File "<frozen importlib._bootstrap_external>", line 994, in exec_module
  File "<frozen importlib._bootstrap>", line 488, in _call_with_frames_removed
  File "E:\delivery-app\delivery-app-abidjan\backend\app\main.py", line 11, in <module>
    from .api import (
  File "E:\delivery-app\delivery-app-abidjan\backend\app\api\deliveries.py", line 16, in <module>
    from ..services.delivery import get_delivery, get_courier_deliveries
ImportError: cannot import name 'get_courier_deliveries' from 'app.services.delivery' (E:\delivery-app\delivery-app-abidjan\backend\app\services\delivery.py)